Workbook

Sheet Титул
B2: ОТЧЁТ ПО НЕЗАВИСИМОЙ ПРОВЕРКЕ
B4: Контур автоматизации автопарка бензовозов и распределения топлива
B5: BEMOL — сеть АЗС и автопарк бензовозов
B8: СГЕНЕРИРОВАННЫЙ НАБОР ДЛЯ ПРОВЕРКИ МЕТОДИКИ
B10: Предмет проверки | C10: Расчёт заработной платы водителей, планирование и исполнение поставок топлива
B11: Проверяемый период | C11: 2025-09-01 — 2026-09-30
B12: Основание | C12: ТЗ заказчика от 18.09.2026 (два документа): распределение топлива и расходы автопарка
B13: Методика | C13: Методика внутреннего аудита информационных систем: тестирование дизайна и операционной эффективности контролей, тесты по существу на полной популяции (формат отчёта Big-4)
B14: Исполнитель | C14: Группа сопровождения контура «Автопарк»
B15: Дата отчёта | C15: 2026-09-19
B16: Объём популяции | C16: 3534 рейсов, 10576 позиций груза, 77 резервуаров, 14 бензовозов, 22 водителей
B17: Выполнено проверок | C17: 56616 объектов по 13 процедурам
B19: ЗАКЛЮЧЕНИЕ
B20: Контрольная среда неэффективна
B21: Выявлены отклонения высокой значимости: числа, которые контур выдаёт бухгалтерии и руководству, не могут использоваться без ручной перепроверки до устранения находок.
A24: Ограничения проверки
A25: 1. Аудит проверяет внутреннюю непротиворечивость системы и соответствие её собственным правилам. Он не подтверждает достоверность исходных данных: что бензовоз физически проехал маршрут, а в резервуар фактически поступили литры.
A26: 2. Фактический пробег и расход топлива принимаются в том виде, в каком их передаёт GPS-прослойка; независимая сверка с показаниями провайдера в объём работы не входила.
A27: 3. Остатки в резервуарах приняты по данным контура. Сверка с Petrol Expert и инвентаризацией не проводилась — интеграция не подключена.
A28: 4. Заключение относится к периоду и набору данных, указанным на титульном листе, и не распространяется на последующие изменения конфигурации.

Sheet Резюме
A2: Резюме для руководства
A3: Счётчики ниже — формулы по листам «Находки» и «Контроли»: правка реестра меняет резюме сама.
A5: НАХОДОК: ВЫСОКОЙ | D5: НАХОДОК: СРЕДНЕЙ | G5: НАХОДОК: НИЗКОЙ | J5: КОНТРОЛЕЙ ЭФФЕКТИВНЫ
A6: =COUNTIF(Находки!$B:$B,"Высокий") | D6: =COUNTIF(Находки!$B:$B,"Средний") | G6: =COUNTIF(Находки!$B:$B,"Низкий") | J6: =COUNTIF(Контроли!$H:$H,"Эффективен")
A7: требуют устранения до эксплуатации | D7: устранить в согласованный срок | G7: принять к сведению | J7: из 13 контролей контура
A9: ПРОВЕРЕНО ОБЪЕКТОВ | D9: ВЫЯВЛЕНО ОТКЛОНЕНИЙ | G9: ДОЛЯ ОТКЛОНЕНИЙ | J9: ДЕНЕЖНАЯ ОЦЕНКА
A10: 56616 | D10: 616 | G10: 0.0109 | J10: 1219811.1
A11: полная популяция, не выборка | D11: каждое расшифровано на листе «Отклонения» | G11: отклонений к проверенным объектам | J11: лей: лишний пробег, перерасход, потери
B14: Значимость | C14: Находок | E14: Оценка | F14: Контролей
B15: Высокий | C15: =COUNTIF(Находки!$B:$B,"Высокий") | E15: Эффективен | F15: =COUNTIF(Контроли!$H:$H,"Эффективен")
B16: Средний | C16: =COUNTIF(Находки!$B:$B,"Средний") | E16: Требует улучшения | F16: =COUNTIF(Контроли!$H:$H,"Требует улучшения")
B17: Низкий | C17: =COUNTIF(Находки!$B:$B,"Низкий") | E17: Неэффективен | F17: =COUNTIF(Контроли!$H:$H,"Неэффективен")
E18: Не тестировался | F18: =COUNTIF(Контроли!$H:$H,"Не тестировался")
A37: Как читать заключение
A38: • «Контрольная среда неэффективна» — Выявлены отклонения высокой значимости: числа, которые контур выдаёт бухгалтерии и руководству, не могут использоваться без ручной перепроверки до устранения находок.
A39: • Значимость находки не назначается экспертно: она выводится из доли отклонений и денежной оценки по шкале на листе «Методика».
A40: • Контроль с дефектом дизайна не получает оценку выше «требует улучшения», даже если отклонений в периоде не найдено: контроль, который легко обойти, не доказан отсутствием попыток обхода.
A41: • Оценка «не тестировался» означает, что в данных нет реквизита для проверки. Это не «всё хорошо» — это отсутствие доказательства.
A43: Предмет проверки
A44: 1. Расчёт заработной платы водителей бензовозов по нормативному пробегу (ТЗ «Автоматизация расчёта расходов автопарка» от 18.09.2026).
A45: 2. Планирование потребности АЗС в топливе, формирование и исполнение рейсов (ТЗ «Автоматизация распределения топлива» от 18.09.2026).
A46: 3. Контроль фактического пробега и расхода дизельного топлива бензовозами.
A47: 4. Настройки контура, действующие по периодам: ставка за километр, лимиты резервуаров, состав отсеков и групп АЗС.

Sheet Панель BI
A2: BI-панель контура
A3: Измените значение в жёлтой ячейке — показатели и диаграммы пересчитаются в Excel без выгрузки заново.
B6: Месяц | C6: Все | E6: Регион | F6: Все | H6: Продукт | I6: Все | K6: Тип рейса | L6: Все
B9: Поставки — срез по месяцу, региону и продукту
B10: ПРИНЯТО НА АЗС, Л | E10: ПОЗИЦИЙ ГРУЗА | H10: ПОТЕРИ ПРИ ПРИЁМКЕ, Л | K10: ОЦЕНКА ПОТЕРЬ, ЛЕЙ
B11: =SUMPRODUCT(Куб!$H$2:$H$274,Куб!$D$2:$D$274) | E11: =SUMPRODUCT(Куб!$H$2:$H$274,Куб!$E$2:$E$274) | H11: =SUMPRODUCT(Куб!$H$2:$H$274,Куб!$F$2:$F$274) | K11: =SUMPRODUCT(Куб!$H$2:$H$274,Куб!$G$2:$G$274)
B12: по выбранному срезу | E12: отсеков слито | H12: загружено минус принято | K12: по цене продукта
B14: Рейсы и оплата — срез по месяцу и типу рейса
B15: РЕЙСОВ | E15: НОРМАТИВНЫЙ ПРОБЕГ, КМ | H15: ЛИШНИЙ ПРОБЕГ, КМ | K15: НАЧИСЛЕНО, ЛЕЙ
B16: =SUMPRODUCT(КубРейсы!$J$2:$J$27,КубРейсы!$C$2:$C$27) | E16: =SUMPRODUCT(КубРейсы!$J$2:$J$27,КубРейсы!$D$2:$D$27) | H16: =SUMPRODUCT(КубРейсы!$J$2:$J$27,КубРейсы!$F$2:$F$27) | K16: =SUMPRODUCT(КубРейсы!$J$2:$J$27,КубРейсы!$G$2:$G$27)
B17: без черновиков | E17: основание для оплаты | H17: факт сверх норматива | K17: зарплата водителей по срезу
B19: Данные диаграмм — пересчитываются вместе со срезом
B20: Продукт | C20: Принято, л
B21: A92 | C21: =SUMPRODUCT((Куб!$C$2:$C$274=$B21)*Куб!$H$2:$H$274*Куб!$D$2:$D$274)
B22: A95 | C22: =SUMPRODUCT((Куб!$C$2:$C$274=$B22)*Куб!$H$2:$H$274*Куб!$D$2:$D$274)
B23: DIESEL | C23: =SUMPRODUCT((Куб!$C$2:$C$274=$B23)*Куб!$H$2:$H$274*Куб!$D$2:$D$274)
B24: GPL | C24: =SUMPRODUCT((Куб!$C$2:$C$274=$B24)*Куб!$H$2:$H$274*Куб!$D$2:$D$274)
B26: Месяц | C26: Принято, л | D26: Начислено, лей
B27: сентябрь 2025 | C27: =SUMPRODUCT((Куб!$A$2:$A$274="2025-09")*Куб!$I$2:$I$274*Куб!$D$2:$D$274) | D27: =SUMPRODUCT((КубРейсы!$A$2:$A$27="2025-09")*КубРейсы!$K$2:$K$27*КубРейсы!$G$2:$G$27)
B28: октябрь 2025 | C28: =SUMPRODUCT((Куб!$A$2:$A$274="2025-10")*Куб!$I$2:$I$274*Куб!$D$2:$D$274) | D28: =SUMPRODUCT((КубРейсы!$A$2:$A$27="2025-10")*КубРейсы!$K$2:$K$27*КубРейсы!$G$2:$G$27)
B29: ноябрь 2025 | C29: =SUMPRODUCT((Куб!$A$2:$A$274="2025-11")*Куб!$I$2:$I$274*Куб!$D$2:$D$274) | D29: =SUMPRODUCT((КубРейсы!$A$2:$A$27="2025-11")*КубРейсы!$K$2:$K$27*КубРейсы!$G$2:$G$27)
B30: декабрь 2025 | C30: =SUMPRODUCT((Куб!$A$2:$A$274="2025-12")*Куб!$I$2:$I$274*Куб!$D$2:$D$274) | D30: =SUMPRODUCT((КубРейсы!$A$2:$A$27="2025-12")*КубРейсы!$K$2:$K$27*КубРейсы!$G$2:$G$27)
B31: январь 2026 | C31: =SUMPRODUCT((Куб!$A$2:$A$274="2026-01")*Куб!$I$2:$I$274*Куб!$D$2:$D$274) | D31: =SUMPRODUCT((КубРейсы!$A$2:$A$27="2026-01")*КубРейсы!$K$2:$K$27*КубРейсы!$G$2:$G$27)
B32: февраль 2026 | C32: =SUMPRODUCT((Куб!$A$2:$A$274="2026-02")*Куб!$I$2:$I$274*Куб!$D$2:$D$274) | D32: =SUMPRODUCT((КубРейсы!$A$2:$A$27="2026-02")*КубРейсы!$K$2:$K$27*КубРейсы!$G$2:$G$27)
B33: март 2026 | C33: =SUMPRODUCT((Куб!$A$2:$A$274="2026-03")*Куб!$I$2:$I$274*Куб!$D$2:$D$274) | D33: =SUMPRODUCT((КубРейсы!$A$2:$A$27="2026-03")*КубРейсы!$K$2:$K$27*КубРейсы!$G$2:$G$27)
B34: апрель 2026 | C34: =SUMPRODUCT((Куб!$A$2:$A$274="2026-04")*Куб!$I$2:$I$274*Куб!$D$2:$D$274) | D34: =SUMPRODUCT((КубРейсы!$A$2:$A$27="2026-04")*КубРейсы!$K$2:$K$27*КубРейсы!$G$2:$G$27)
B35: май 2026 | C35: =SUMPRODUCT((Куб!$A$2:$A$274="2026-05")*Куб!$I$2:$I$274*Куб!$D$2:$D$274) | D35: =SUMPRODUCT((КубРейсы!$A$2:$A$27="2026-05")*КубРейсы!$K$2:$K$27*КубРейсы!$G$2:$G$27)
B36: июнь 2026 | C36: =SUMPRODUCT((Куб!$A$2:$A$274="2026-06")*Куб!$I$2:$I$274*Куб!$D$2:$D$274) | D36: =SUMPRODUCT((КубРейсы!$A$2:$A$27="2026-06")*КубРейсы!$K$2:$K$27*КубРейсы!$G$2:$G$27)
B37: июль 2026 | C37: =SUMPRODUCT((Куб!$A$2:$A$274="2026-07")*Куб!$I$2:$I$274*Куб!$D$2:$D$274) | D37: =SUMPRODUCT((КубРейсы!$A$2:$A$27="2026-07")*КубРейсы!$K$2:$K$27*КубРейсы!$G$2:$G$27)
B38: август 2026 | C38: =SUMPRODUCT((Куб!$A$2:$A$274="2026-08")*Куб!$I$2:$I$274*Куб!$D$2:$D$274) | D38: =SUMPRODUCT((КубРейсы!$A$2:$A$27="2026-08")*КубРейсы!$K$2:$K$27*КубРейсы!$G$2:$G$27)
B39: сентябрь 2026 | C39: =SUMPRODUCT((Куб!$A$2:$A$274="2026-09")*Куб!$I$2:$I$274*Куб!$D$2:$D$274) | D39: =SUMPRODUCT((КубРейсы!$A$2:$A$27="2026-09")*КубРейсы!$K$2:$K$27*КубРейсы!$G$2:$G$27)
B41: Процедура | C41: Отклонений | D41: Название
B42: T-01 | C42: 18 | D42: Пересчёт заработной платы водителей
B43: T-02 | C43: 0 | D43: Целостность периодов действия ставки
B44: T-03 | C44: 10 | D44: Слив отсеками целиком
B45: T-04 | C45: 5 | D45: Контроль переполнения резервуара
B46: T-05 | C46: 197 | D46: Сверка отгрузки и приёмки
B47: T-06 | C47: 151 | D47: Необоснованный пробег
B48: T-07 | C48: 96 | D48: Перерасход топлива бензовозом
B49: T-08 | C49: 19 | D49: Полнота учёта рейса
...

Sheet Контроли
A2: Матрица контролей
A3: Дизайн — предотвращает ли правило ошибку в принципе. Эффективность — сработало ли оно на данных периода.
A5: Код | B5: Область | C5: Контроль | D5: Цель контроля | E5: Тип | F5: Дизайн | G5: Эффективность | H5: Итоговая оценка | I5: Покрытие | J5: Проверено | K5: Отклонений | L5: Оценка, лей
A6: FLT-C-01 | B6: Расчёты с персоналом | C6: Автоматический расчёт зарплаты по нормативу | D6: Зарплата водителя рассчитывается системой по нормативному пробегу и не вводится вручную. | E6: Автоматический | F6: Эффективен | G6: Требует улучшения | H6: Требует улучшения | I6: 100 % популяции | J6: 3515 | K6: 18 | L6: 2622.71
A7: FLT-C-02 | B7: Расчёты с персоналом | C7: Ставка применяется по дате рейса | D7: Изменение ставки не переписывает начисления закрытых периодов. | E7: Автоматический | F7: Эффективен | G7: Требует улучшения | H7: Требует улучшения | I7: 100 % популяции | J7: 3516 | K7: 18 | L7: 2622.71
A8: FLT-C-03 | B8: Операции: отгрузка и приёмка | C8: Слив отсеками целиком | D8: Плановый объём позиции равен паспортному объёму отсека. | E8: Автоматический | F8: Эффективен | G8: Требует улучшения | H8: Требует улучшения | I8: 100 % популяции | J8: 10576 | K8: 10 | L8: 0
A9: FLT-C-04 | B9: Операции: отгрузка и приёмка | C9: Запрет переполнения резервуара | D9: Приёмка не превышает свободную ёмкость резервуара. | E9: Автоматический | F9: Эффективен | G9: Требует улучшения | H9: Требует улучшения | I9: 100 % популяции | J9: 10576 | K9: 5 | L9: 0
A10: FLT-C-05 | B10: Операции: отгрузка и приёмка | C10: Сверка отгруженного и принятого | D10: Расхождение выявляется и фиксируется по каждой поставке. | E10: Автоматический | F10: Эффективен | G10: Требует улучшения | H10: Требует улучшения | I10: 100 % популяции | J10: 10576 | K10: 197 | L10: 1132934.4
A11: FLT-C-06 | B11: Контроль затрат | C11: Контроль необоснованного пробега | D11: Превышение факта над нормативом выявляется и оценивается в деньгах. | E11: Автоматический | F11: Эффективен | G11: Требует улучшения | H11: Требует улучшения | I11: 100 % популяции | J11: 3534 | K11: 151 | L11: 30259.6
A12: FLT-C-07 | B12: Контроль затрат | C12: Контроль расхода топлива бензовозом | D12: Перерасход против нормы автомобиля выявляется. | E12: Автоматический | F12: Эффективен | G12: Требует улучшения | H12: Требует улучшения | I12: 100 % популяции | J12: 3534 | K12: 96 | L12: 53994.44
A13: FLT-C-08 | B13: Полнота и достоверность учёта | C13: Полнота реквизитов рейса | D13: Утверждённый рейс содержит груз, норматив и начисление. | E13: Автоматический | F13: Эффективен | G13: Требует улучшения | H13: Требует улучшения | I13: 100 % популяции | J13: 3534 | K13: 19 | L13: 0
A14: FLT-C-09 | B14: Полнота и достоверность учёта | C14: Цепочка статусов исполнения | D14: Документ нельзя оформить задним числом, пропустив стадии. | E14: Автоматический | F14: Требует улучшения | G14: Требует улучшения | H14: Требует улучшения | I14: 100 % популяции | J14: 3534 | K14: 35 | L14: 0
A15: FLT-C-10 | B15: Доступ и полномочия | C15: Разделение полномочий «создал / утвердил» | D15: Одно лицо не создаёт и не утверждает один и тот же рейс. | E15: Ручной | F15: Требует улучшения | G15: Требует улучшения | H15: Требует улучшения | I15: Выборка | J15: 3534 | K15: 74 | L15: 0
A16: FLT-C-11 | B16: Полнота и достоверность учёта | C16: Защита от двойного учёта | D16: Рейс и путевой лист не учитываются дважды. | E16: Автоматический | F16: Эффективен | G16: Требует улучшения | H16: Требует улучшения | I16: 100 % популяции | J16: 3534 | K16: 3 | L16: 0
A17: FLT-C-12 | B17: Справочные данные | C17: Непротиворечивость справочников | D17: Паспортные величины не противоречат друг другу. | E17: Автоматический | F17: Эффективен | G17: Требует улучшения | H17: Требует улучшения | I17: 100 % популяции | J17: 91 | K17: 2 | L17: 0
A18: FLT-C-13 | B18: Непрерывность операций | C18: Покрытие страхового запаса планом завоза | D18: АЗС не останавливает продажу из-за отсутствия топлива. | E18: Автоматический | F18: Эффективен | G18: Неэффективен | H18: Неэффективен | I18: 100 % популяции | J18: 77 | K18: 6 | L18: 0
A20: Обоснование оценки дизайна
A21: Почему контроль признан эффективным или требующим улучшения — и какой процедурой это проверено.
A23: Код | B23: Как контроль реализован в системе | C23: Процедуры проверки
A24: FLT-C-01 | B24: Начисление формируется представлением V_FLT_TRIP_PAY; поля для ручного ввода суммы в интерфейсе нет. | C24: T-01
A25: FLT-C-02 | B25: Ставки хранятся периодами (FLT_RATE_PERIODS), резолвер выбирает период по TRIP_DATE, а не по SYSDATE. | C25: T-02, T-01
A26: FLT-C-03 | B26: Подбор отсеков — точное перечисление подмножеств (supply_rules.pick_sections), частичный объём сформировать нельзя. | C26: T-03
A27: FLT-C-04 | B27: Валидация на сервере (supply_rules.validate_loads); проверка выполняется до сохранения факта. | C27: T-04
A28: FLT-C-05 | B28: Карточка исполнения показывает три величины (загружено / по документам / принято) и подсвечивает разницу. | C28: T-05
A29: FLT-C-06 | B29: Порог отклонения — настройка заказчика (KM_DEVIATION_LIMIT), факт приходит из GPS-прослойки. | C29: T-06
A30: FLT-C-07 | B30: Норма хранится в карточке автомобиля (NORM_L_PER_100KM), расчёт нормы рейса автоматический. | C30: T-07
A31: FLT-C-08 | B31: Утверждение недоступно для рейса без позиций; нормативный пробег считается при сохранении маршрута. | C31: T-08
A32: FLT-C-09 | B32: Порядок задан справочником REF_TRIP_STATUS.SORT_NO, но запрет обратного перехода реализован в контроллере, а не ограничением БД — прямая правка таблицы его обойдёт. | C32: T-09
A33: FLT-C-10 | B33: Роли в системе разделены, но техническая блокировка самоутверждения не включена: контроль держится на распределении учётных записей. | C33: T-10
A34: FLT-C-11 | B34: Один бензовоз используется в плане один раз; номер путевого листа уникален. | C34: T-11
... A36: FLT-C-13 | B36: Планирование сортирует потребности по дням до страхового запаса; сводка руководителя показывает риск. | C36: T-13

Sheet Находки
A2: Реестр находок
A3: Три последние колонки — для ответа руководства; их заполняет заказчик, остальное считает проверка.
A5: № | B5: Значимость | C5: Контроль | D5: Тест | E5: Наблюдение | F5: Риск | G5: Рекомендация | H5: Отклонений | I5: Проверено | J5: Доля | K5: Оценка, лей | L5: Вероятн. 1–5 | M5: Влияние 1–5 | N5: Ответственный | O5: Срок | P5: Статус устранения
A6: F-01 | B6: Высокий | C6: FLT-C-05 | D6: T-05 | E6: При проверке 10576 объектов (100 % позиций с зафиксированными отгрузкой и приёмкой) выявлено 197 отклонений (1.86 %). Денежная оценка: 1 132 934.40 лея. | F6: Систематическая недостача при приёмке — признак потерь продукта или недолива на нефтебазе. | G6: Ввести разбор каждой недостачи выше допуска с обязательным комментарием и сверкой с нефтебазой. | H6: 197 | I6: 10576 | J6: 0.0186 | K6: 1132934.4 | L6: 3 | M6: 5
A7: F-02 | B7: Высокий | C7: FLT-C-07 | D7: T-07 | E7: При проверке 3534 объектов (100 % рейсов с зафиксированной заправкой) выявлено 96 отклонений (2.72 %). Денежная оценка: 53 994.44 лея. | F7: Перерасход топлива бензовозом — прямой убыток и возможный слив на сторону. | G7: Сверять заправки бензовозов с топливными картами и разбирать рейсы с отклонением выше порога. | H7: 96 | I7: 3534 | J7: 0.0272 | K7: 53994.44 | L7: 3 | M7: 5
A8: F-03 | B8: Высокий | C8: FLT-C-13 | D8: T-13 | E8: При проверке 77 объектов (100 % резервуаров сети) выявлено 6 отклонений (7.79 %). | F8: Остановка продажи на АЗС из-за отсутствия топлива — потерянная выручка и репутационный ущерб. | G8: Включить резервуары ниже страхового запаса в план завоза принудительно, с уведомлением логисту. | H8: 6 | I8: 77 | J8: 0.0779 | K8: 0 | L8: 4 | M8: 2
A9: F-04 | B9: Средний | C9: FLT-C-06 | D9: T-06 | E9: При проверке 3534 объектов (100 % рейсов с зафиксированным фактическим пробегом) выявлено 151 отклонений (4.27 %). Денежная оценка: 30 259.60 лея. | F9: Лишние километры оплачиваются водителю и не создают поставки. | G9: Требовать обоснование при утверждении рейса с отклонением выше порога. | H9: 151 | I9: 3534 | J9: 0.0427 | K9: 30259.6 | L9: 3 | M9: 4
A10: F-05 | B10: Средний | C10: FLT-C-10 | D10: T-10 | E10: При проверке 3534 объектов (100 % утверждённых рейсов с заполненными автором и утвердившим) выявлено 74 отклонений (2.09 %). | F10: Самоутверждение рейса снимает единственный контроль над основанием для начисления зарплаты. | G10: Включить техническую блокировку: утвердить рейс может только учётная запись, отличная от создавшей. | H10: 74 | I10: 3534 | J10: 0.0209 | K10: 0 | L10: 3 | M10: 2
A11: F-06 | B11: Средний | C11: FLT-C-12 | D11: T-12 | E11: При проверке 91 объектов (100 % резервуаров и бензовозов) выявлено 2 отклонений (2.20 %). | F11: Ошибка в справочнике тиражируется во все расчёты периода и обнаруживается только при инвентаризации. | G11: Проверять неравенства при сохранении карточки и ежемесячно прогонять контроль справочников. | H11: 2 | I11: 91 | J11: 0.022 | K11: 0 | L11: 3 | M11: 1
A12: F-07 | B12: Низкий | C12: FLT-C-01 | D12: T-01 | E12: При проверке 3515 объектов (100 % рейсов периода со статусом не «черновик») выявлено 18 отклонений (0.51 %). Денежная оценка: 2 622.71 лея. | F12: Начисление, не соответствующее нормативу, попадает в расчётную ведомость и в себестоимость литра. | G12: Заблокировать сохранение рейса, у которого начисление отличается от расчётного, и вывести расхождение в журнал для разбора. | H12: 18 | I12: 3515 | J12: 0.0051 | K12: 2622.71 | L12: 2 | M12: 3
A13: F-08 | B13: Низкий | C13: FLT-C-03 | D13: T-03 | E13: При проверке 10576 объектов (100 % позиций рейсов с назначенным отсеком) выявлено 10 отклонений (0.09 %). | F13: Частичный слив нечем измерить: остаток в отсеке становится неучтённым топливом. | G13: Оставить подбор отсеков только автоматическим, ручное изменение объёма позиции запретить. | H13: 10 | I13: 10576 | J13: 0.0009 | K13: 0 | L13: 1 | M13: 2
A14: F-09 | B14: Низкий | C14: FLT-C-04 | D14: T-04 | E14: При проверке 10576 объектов (100 % позиций с зафиксированным объёмом) выявлено 5 отклонений (0.05 %). | F14: Перелив резервуара — пролив продукта, экологический инцидент и прямые потери. | G14: Держать проверку на сервере (не в форме) и логировать каждую попытку превышения. | H14: 5 | I14: 10576 | J14: 0.0005 | K14: 0 | L14: 1 | M14: 1
A15: F-10 | B15: Низкий | C15: FLT-C-08 | D15: T-08 | E15: При проверке 3534 объектов (100 % рейсов периода со статусом не «черновик») выявлено 19 отклонений (0.54 %). | F15: Неполный рейс не может служить основанием для начисления и списания, но участвует в отчётности. | G15: Запретить утверждение рейса без позиций груза и рассчитанного норматива. | H15: 19 | I15: 3534 | J15: 0.0054 | K15: 0 | L15: 2 | M15: 2
A16: F-11 | B16: Низкий | C16: FLT-C-09 | D16: T-09 | E16: При проверке 3534 объектов (100 % рейсов с журналом статусов) выявлено 35 отклонений (0.99 %). | F16: Оформление задним числом скрывает простои и фактические сроки доставки. | G16: Перенести проверку порядка статусов в ограничение базы данных (триггер), чтобы её нельзя было обойти прямой правкой таблицы. | H16: 35 | I16: 3534 | J16: 0.0099 | K16: 0 | L16: 2 | M16: 2
A17: F-12 | B17: Низкий | C17: FLT-C-11 | D17: T-11 | E17: При проверке 3534 объектов (100 % рейсов периода со статусом не «черновик») выявлено 3 отклонений (0.08 %). | F17: Двойной учёт рейса удваивает и зарплату, и списание топлива. | G17: Добавить уникальный ключ на номер путевого листа и предупреждение при повторной постановке бензовоза. | H17: 3 | I17: 3534 | J17: 0.0008 | K17: 0 | L17: 1 | M17: 1
A19: Заполняет заказчик
A20: • Жёлтые ячейки колонок «Ответственный», «Срок» и «Статус устранения» — единственные, которые вносит заказчик. Например: «Морару И., руководитель транспортного отдела» / «31.10.2026» / «Принято, в работе».
A21: • Остальные колонки рассчитаны проверкой; их правка разрывает связь с листами «Тесты» и «Отклонения» и делает отчёт непроверяемым.
A22: • Значимость: «Высокий» — доля отклонений ≥ 5 % либо денежная оценка ≥ 50 000 лей; «Средний» — ≥ 1 % либо ≥ 5 000 лей; «Низкий» — всё остальное.

Sheet Карта рисков
A2: Карта рисков: вероятность × влияние
A3: Обе координаты выведены из результата тестирования — из доли отклонений и денежной оценки, а не назначены.
B6: ВЛИЯНИЕ | C6: 5 | F6: F-01, F-02
C7: 4 | F7: F-04
C8: 3 | E8: F-07
C9: 2 | D9: F-08 | E9: F-10, F-11 | F9: F-05 | G9: F-03
C10: 1 | D10: F-09, F-12 | F10: F-06
D11: 1 | E11: 2 | F11: 3 | G11: 4 | H11: 5
D12: ВЕРОЯТНОСТЬ
A14: Находки на карте
A16: № | B16: Находка | C16: Значимость | D16: Вероятность | E16: Влияние | F16: Ранг
A17: F-01 | B17: Сверка отгрузки и приёмки | C17: Высокий | D17: 3 | E17: 5 | F17: 15
A18: F-02 | B18: Перерасход топлива бензовозом | C18: Высокий | D18: 3 | E18: 5 | F18: 15
A19: F-04 | B19: Необоснованный пробег | C19: Средний | D19: 3 | E19: 4 | F19: 12
A20: F-03 | B20: Покрытие страхового запаса | C20: Высокий | D20: 4 | E20: 2 | F20: 8
A21: F-05 | B21: Разделение полномочий | C21: Средний | D21: 3 | E21: 2 | F21: 6
A22: F-07 | B22: Пересчёт заработной платы водителей | C22: Низкий | D22: 2 | E22: 3 | F22: 6
A23: F-10 | B23: Полнота учёта рейса | C23: Низкий | D23: 2 | E23: 2 | F23: 4
A24: F-11 | B24: Хронология исполнения рейса | C24: Низкий | D24: 2 | E24: 2 | F24: 4
A25: F-06 | B25: Непротиворечивость справочников | C25: Средний | D25: 3 | E25: 1 | F25: 3
A26: F-08 | B26: Слив отсеками целиком | C26: Низкий | D26: 1 | E26: 2 | F26: 2
A27: F-09 | B27: Контроль переполнения резервуара | C27: Низкий | D27: 1 | E27: 1 | F27: 1
A28: F-12 | B28: Дублирование документов | C28: Низкий | D28: 1 | E28: 1 | F28: 1
A30: Шкала
A31: • Вероятность 5 — отклонения более чем в 10 % проверенных объектов; 4 — свыше 5 %; 3 — свыше 1 %; 2 — свыше 0,1 %; 1 — единичные.
A32: • Влияние 5 — денежная оценка от 50 000 лей; 4 — от 5 000; 3 — от 500; 2 — оценка ниже 500 лей либо более пяти случаев; 1 — единичный случай без денежной оценки.
A33: • Ранг = вероятность × влияние. Красная зона — устранять до перевода контура в промышленную эксплуатацию.

Sheet Тесты
A2: Выполненные процедуры
A3: Пересчёт выполнен отдельной реализацией формул, не использующей проверяемый код: совпадение результата не может быть следствием общей ошибки.
A5: Код | B5: Процедура | C5: Что должно выполняться | D5: Как проверено | E5: Охват | F5: Проверено | G5: Отклонений | H5: Доля | I5: Оценка, лей | J5: Результат
A6: T-01 | B6: Пересчёт заработной платы водителей | C6: Начисление соответствует нормативному пробегу и ставке, действовавшей на дату рейса. | D6: Пересчёт: норм. км × ставка(дата рейса) + доплата за внутренний рейс. Сравнение с начислением в системе, допуск 0,01 лея. | E6: 100 % рейсов периода со статусом не «черновик» | F6: 3515 | G6: 18 | H6: 0.0051 | I6: 2622.71 | J6: Отклонения
A7: T-02 | B7: Целостность периодов действия ставки | C7: На любую дату действует ровно одна ставка; изменение ставки не меняет уже начисленное за прошлый период. | D7: Сортировка периодов по дате начала, проверка смежности: предыдущий закрыт строго до начала следующего. | E7: 100 % периодов действия ставки | F7: 1 | G7: 0 | H7: 0 | I7: 0 | J7: Без отклонений
A8: T-03 | B8: Слив отсеками целиком | C8: Отсек бензовоза сливается на АЗС полностью: частичный слив ТЗ запрещает (нет поверенного средства измерения остатка в отсеке). | D8: Сверка планового объёма каждой позиции с паспортным объёмом назначенного отсека, допуск 0,5 л. | E8: 100 % позиций рейсов с назначенным отсеком | F8: 10576 | G8: 10 | H8: 0.0009 | I8: 0 | J8: Отклонения
A9: T-04 | B9: Контроль переполнения резервуара | C9: Приёмка не может превысить допустимый налив резервуара, а для ещё не выполненной поставки — свободную ёмкость на сегодня. | D9: Для запланированных поставок: приёмка против (допустимый налив − остаток). Для исполненных: приёмка против допустимого налива (состояние резервуара на дату слива контур не хранит). Допуск 0,5 л. | E9: 100 % позиций с зафиксированным объёмом | F9: 10576 | G9: 5 | H9: 0.0005 | I9: 0 | J9: Отклонения
A10: T-05 | B10: Сверка отгрузки и приёмки | C10: Расхождение между налитым на нефтебазе и принятым на АЗС не превышает технологического допуска. | D10: Разница «загружено − принято» по каждой позиции против допуска 50 л; денежная оценка по цене ДТ. | E10: 100 % позиций с зафиксированными отгрузкой и приёмкой | F10: 10576 | G10: 197 | H10: 0.0186 | I10: 1132934.4 | J10: Отклонения
A11: T-06 | B11: Необоснованный пробег | C11: Фактический пробег не превышает нормативный более чем на 5 %. | D11: Расчёт отклонения по каждому рейсу с фактом GPS; денежная оценка лишних километров по действующей ставке. | E11: 100 % рейсов с зафиксированным фактическим пробегом | F11: 3534 | G11: 151 | H11: 0.0427 | I11: 30259.6 | J11: Отклонения
A12: T-07 | B12: Перерасход топлива бензовозом | C12: Фактический расход ДТ не превышает норму автомобиля более чем на 5 %. | D12: Норма рейса = норм. км × норма л/100 км автомобиля; сравнение с фактической заправкой, денежная оценка по цене ДТ. | E12: 100 % рейсов с зафиксированной заправкой | F12: 3534 | G12: 96 | H12: 0.0272 | I12: 53994.44 | J12: Отклонения
A13: T-08 | B13: Полнота учёта рейса | C13: Утверждённый рейс содержит груз, нормативный пробег и начисление — иначе он не может быть основанием ни для зарплаты, ни для списания топлива. | D13: Проверка наличия связанных записей у каждого рейса не в статусе «черновик». | E13: 100 % рейсов периода со статусом не «черновик» | F13: 3534 | G13: 19 | H13: 0.0054 | I13: 0 | J13: Отклонения
A14: T-09 | B14: Хронология исполнения рейса | C14: Статусы меняются строго по цепочке: заявка → загрузка → в пути → доставлено → утверждено. Пропуск стадии означает, что документ оформлен задним числом. | D14: Проверка последовательности записей журнала статусов каждого рейса против эталонной цепочки. | E14: 100 % рейсов с журналом статусов | F14: 3534 | G14: 35 | H14: 0.0099 | I14: 0 | J14: Отклонения
A15: T-10 | B15: Разделение полномочий | C15: Создание рейса и его утверждение выполняют разные сотрудники: утверждённый рейс — основание для начисления зарплаты. | D15: Сравнение автора и утвердившего по каждому утверждённому рейсу. | E15: 100 % утверждённых рейсов с заполненными автором и утвердившим | F15: 3534 | G15: 74 | H15: 0.0209 | I15: 0 | J15: Отклонения
A16: T-11 | B16: Дублирование документов | C16: Один и тот же рейс не может быть учтён дважды — ни через второй путевой лист, ни через полностью повторённый документ. | D16: Поиск повторов по номеру путевого листа и по полному совпадению реквизитов (бензовоз, дата, водитель, нормативный пробег) по всей популяции рейсов. Два разных рейса одной машины за день отклонением не считаются. | E16: 100 % рейсов периода со статусом не «черновик» | F16: 3534 | G16: 3 | H16: 0.0008 | I16: 0 | J16: Отклонения
A17: T-12 | B17: Непротиворечивость справочников | C17: Паспортные величины резервуаров и бензовозов не противоречат друг другу: на них опираются все последующие расчёты. | D17: Проверка неравенств: налив ≤ ёмкость, страховой запас ≤ налив, остаток ≤ ёмкость, сумма отсеков = ёмкость цистерны. | E17: 100 % резервуаров и бензовозов | F17: 91 | G17: 2 | H17: 0.022 | I17: 0 | J17: Отклонения
A18: T-13 | B18: Покрытие страхового запаса | C18: Резервуар с остатком ниже страхового запаса включён в план завоза: иначе АЗС останавливает продажу. | D18: Сопоставление резервуаров ниже страхового запаса с позициями запланированных рейсов. | E18: 100 % резервуаров сети | F18: 77 | G18: 6 | H18: 0.0779 | I18: 0 | J18: Отклонения
A20: Методика
A21: 1. Тестирование полной популяции (data & analytics): каждый документ периода пересчитан независимо, выборочный метод применён только там, где контроль не отражён в данных.
A22: 2. Пересчёт выполнен отдельной реализацией формул (modules/autopark/audit.py), не использующей проверяемый код расчёта, — совпадение результата не может быть следствием общей ошибки.
A23: 3. Оценка контроля даётся по двум измерениям: дизайн (предотвращает ли правило ошибку в принципе) и операционная эффективность (срабатывало ли оно на данных периода).
A24: 4. Контроль с дефектом дизайна не получает оценку выше «требует улучшения», даже если отклонений в периоде не обнаружено.
A25: 5. Значимость находки определяется долей отклонений и денежной оценкой, а не экспертным суждением.

Sheet Отклонения
A2: Расшифровка отклонений
A3: Каждый выявленный случай с реквизитами документа — чтобы находку можно было проверить, а не принять на веру.
A5: T-01 · Пересчёт заработной платы водителей · отклонений: 18 из 3515 проверенных
A6: Рейс | B6: Дата | C6: Водитель | D6: Тип | E6: Норм. км | F6: Ставка | G6: Пересчёт аудитора, лей | H6: В системе, лей | I6: Расхождение, лей
A7: 62 | B7: 2025-09-06 | C7: Rusu Victor | D7: DOMESTIC | E7: 189.3 | F7: 2.75 | G7: 1120.58 | H7: 1267.83 | I7: 147.25
A8: 108 | B8: 2025-09-12 | C8: Sirbu Dumitru | D8: DOMESTIC | E8: 258.7 | F8: 2.75 | G8: 1311.42 | H8: 1495.97 | I8: 184.55
A9: 133 | B9: 2025-09-16 | C9: Rotaru Igor | D9: DOMESTIC | E9: 296.7 | F9: 2.75 | G9: 1415.92 | H9: 1520.98 | I9: 105.06
A10: 397 | B10: 2025-10-15 | C10: Cazacu Petru | D10: DOMESTIC | E10: 210.5 | F10: 2.75 | G10: 1178.88 | H10: 1251.18 | I10: 72.31
A11: 516 | B11: 2025-10-29 | C11: Rotaru Dumitru | D11: DOMESTIC | E11: 291.4 | F11: 2.75 | G11: 1401.35 | H11: 1513.41 | I11: 112.06
A12: 723 | B12: 2025-11-24 | C12: Cazacu Mihai | D12: DOMESTIC | E12: 309 | F12: 2.75 | G12: 1449.75 | H12: 1538.33 | I12: 88.58
A13: 990 | B13: 2025-12-22 | C13: Grosu Petru | D13: IMPORT | E13: 977 | F13: 2.75 | G13: 2686.75 | H13: 2934.15 | I13: 247.4
A14: 1563 | B14: 2026-02-23 | C14: Rusu Petru | D14: DOMESTIC | E14: 293.5 | F14: 2.75 | G14: 1407.12 | H14: 1550.23 | I14: 143.11
A15: 1756 | B15: 2026-03-17 | C15: Grosu Petru | D15: DOMESTIC | E15: 399.7 | F15: 2.75 | G15: 1699.17 | H15: 1993.45 | I15: 294.28
A16: 1895 | B16: 2026-03-31 | C16: Popa Mihai | D16: DOMESTIC | E16: 194.6 | F16: 2.75 | G16: 1135.15 | H16: 1219.5 | I16: 84.35
A17: 2002 | B17: 2026-04-11 | C17: Cebotari Andrei | D17: DOMESTIC | E17: 446.8 | F17: 2.75 | G17: 1828.7 | H17: 1906.43 | I17: 77.73
A18: 2433 | B18: 2026-05-29 | C18: Bejan Mihai | D18: DOMESTIC | E18: 232.7 | F18: 2.75 | G18: 1239.92 | H18: 1279.92 | I18: 40
... A24: 3334 | B24: 2026-09-08 | C24: Chirica Igor | D24: DOMESTIC | E24: 320.9 | F24: 3.5 | G24: 1123.15 | H24: 1306.43 | I24: 183.28
A27: T-03 · Слив отсеками целиком · отклонений: 10 из 10576 проверенных
A28: Рейс | B28: АЗС | C28: Продукт | D28: Отсек | E28: Объём отсека, л | F28: В позиции, л | G28: Расхождение, л
A29: 201 | B29: КОМ-24 | C29: A92 | D29: 3 | E29: 4000 | F29: 3171 | G29: -829
A30: 1150 | B30: КОМ-18 | C30: A95 | D30: 27 | E30: 6000 | F30: 4736 | G30: -1264
A31: 1371 | B31: БЭЛ-14 | C31: A92 | D31: 53 | E31: 3000 | F31: 2350 | G31: -650
A32: 1493 | B32: УНГ-05 | C32: DIESEL | D32: 10 | E32: 6000 | F32: 3814 | G32: -2186
A33: 2402 | B33: УНГ-17 | C33: A92 | D33: 13 | E33: 6000 | F33: 4934 | G33: -1066
A34: 2699 | B34: КАГ-09 | C34: A95 | D34: 17 | E34: 4000 | F34: 2846 | G34: -1154
A35: 3377 | B35: УНГ-05 | C35: A92 | D35: 45 | E35: 4000 | F35: 3165 | G35: -835
A36: 3406 | B36: КИШ-19 | C36: A92 | D36: 20 | E36: 5000 | F36: 2918 | G36: -2082
A37: 3428 | B37: УНГ-05 | C37: DIESEL | D37: 15 | E37: 4000 | F37: 3118 | G37: -882
A38: 3487 | B38: УНГ-17 | C38: DIESEL | D38: 19 | E38: 5000 | F38: 2813 | G38: -2187
A41: T-04 · Контроль переполнения резервуара · отклонений: 5 из 10576 проверенных
A42: Рейс | B42: АЗС | C42: Продукт | D42: База сравнения | E42: Допустимый налив, л | F42: Остаток, л | G42: Предел, л | H42: Принято, л | I42: Превышение, л
A43: 917 | B43: КИШ-01 | C43: A92 | D43: допустимый налив резервуара | E43: 28500 | F43: 20728 | G43: 28500 | H43: 29273 | I43: 773
A44: 1102 | B44: ОРХ-16 | C44: A92 | D44: допустимый налив резервуара | E44: 23750 | F44: 15842 | G44: 23750 | H44: 24471 | I44: 721
A45: 1739 | B45: БЭЛ-02 | C45: DIESEL | D45: допустимый налив резервуара | E45: 38000 | F45: 14226 | G45: 38000 | H45: 39950 | I45: 1950
A46: 1958 | B46: ОРХ-10 | C46: A92 | D46: допустимый налив резервуара | E46: 19000 | F46: 13409 | G46: 19000 | H46: 20545 | I46: 1545
A47: 2820 | B47: КАГ-21 | C47: A95 | D47: допустимый налив резервуара | E47: 19000 | F47: 16835 | G47: 19000 | H47: 20314 | I47: 1314
A50: T-05 · Сверка отгрузки и приёмки · отклонений: 197 из 10576 проверенных
A51: Рейс | B51: АЗС | C51: Продукт | D51: Загружено, л | E51: По документам, л | F51: Принято, л | G51: Потери, л | H51: Оценка, лей
A52: 2 | B52: БЭЛ-02 | C52: A92 | D52: 6000 | E52: 6000 | F52: 5588 | G52: 412 | H52: 9640.8
A53: 3 | B53: КИШ-19 | C53: DIESEL | D53: 5000 | E53: 5000 | F53: 4930 | G53: 70 | H53: 1638
...

Sheet Выборка
A2: Аудиторская выборка
A3: Для контролей, которые не видны в данных целиком, проверяется выборка документов.
A5: Как сформирована выборка
A6: • Ключ воспроизводимости: «BEMOL-2026». Состав выборки определяется хешем SHA-256 от ключа и номера документа, а не генератором случайных чисел: та же команда на другой машине и в другом году даст тот же список.
A7: • Объём выборки задан шкалой attribute sampling при ожидаемом нулевом уровне отклонений и доверии 90 %: контроль, срабатывающий ежедневно — 25 документов, еженедельно — 5, ежемесячно — 2.
A8: • Одно отклонение в выборке уже означает, что контроль не может быть признан эффективным: нулевой ожидаемый уровень отклонений не допускает исключений.
A10: Контроль | B10: № | C10: Рейс | D10: Дата | E10: Путевой лист | F10: Создал | G10: Утвердил | H10: Результат
A11: FLT-C-10 | B11: 1 | C11: 94 | D11: 2025-09-10 | E11: AP-40094 | F11: dispecer1 | G11: logist1 | H11: Без отклонений
A12: FLT-C-10 | B12: 2 | C12: 95 | D12: 2025-09-11 | E12: AP-40095 | F12: dispecer2 | G12: logist2 | H12: Без отклонений
A13: FLT-C-10 | B13: 3 | C13: 204 | D13: 2025-09-24 | E13: AP-40204 | F13: dispecer1 | G13: logist2 | H13: Без отклонений
A14: FLT-C-10 | B14: 4 | C14: 347 | D14: 2025-10-09 | E14: AP-40347 | F14: dispecer1 | G14: dispecer1 | H14: Отклонение
A15: FLT-C-10 | B15: 5 | C15: 432 | D15: 2025-10-18 | E15: AP-40432 | F15: dispecer1 | G15: dispecer2 | H15: Без отклонений
A16: FLT-C-10 | B16: 6 | C16: 443 | D16: 2025-10-20 | E16: AP-40443 | F16: logist1 | G16: sef.transport | H16: Без отклонений
A17: FLT-C-10 | B17: 7 | C17: 641 | D17: 2025-11-14 | E17: AP-40641 | F17: dispecer1 | G17: sef.transport | H17: Без отклонений
A18: FLT-C-10 | B18: 8 | C18: 698 | D18: 2025-11-20 | E18: AP-40698 | F18: logist1 | G18: dispecer2 | H18: Без отклонений
A19: FLT-C-10 | B19: 9 | C19: 1017 | D19: 2025-12-24 | E19: AP-41017 | F19: dispecer2 | G19: logist1 | H19: Без отклонений
A20: FLT-C-10 | B20: 10 | C20: 1171 | D20: 2026-01-12 | E20: AP-41171 | F20: logist1 | G20: contabil1 | H20: Без отклонений
A21: FLT-C-10 | B21: 11 | C21: 1248 | D21: 2026-01-20 | E21: AP-41248 | F21: logist2 | G21: dispecer2 | H21: Без отклонений
A22: FLT-C-10 | B22: 12 | C22: 1432 | D22: 2026-02-09 | E22: AP-41432 | F22: dispecer1 | G22: dispecer2 | H22: Без отклонений
... A35: FLT-C-10 | B35: 25 | C35: 3392 | D35: 2026-09-16 | E35: AP-43392 | F35: logist1 | G35: logist1 | H35: Отклонение

Sheet Куб
A1: Месяц | B1: Регион | C1: Продукт | D1: Принято, л | E1: Позиций | F1: Потери, л | G1: Оценка потерь, лей | H1: В срезе | I1: В срезе без месяца
A2: 2025-09 | B2: Бэлць | C2: A92 | D2: 213942 | E2: 44 | F2: 1058 | G2: 25603.6 | H2: =IF(AND(OR('Панель BI'!$C$6="Все","сентябрь 2025"='Панель BI'!$C$6),OR('Панель BI'!$F$6="Все",$B2='Панель BI'!$F$6),OR('Панель BI'!$I$6="Все",$C2='Панель BI'!$I$6)),1,0) | I2: =IF(AND(OR('Панель BI'!$F$6="Все",$B2='Панель BI'!$F$6),OR('Панель BI'!$I$6="Все",$C2='Панель BI'!$I$6)),1,0)
A3: 2025-09 | B3: Бэлць | C3: A95 | D3: 159619 | E3: 32 | F3: 381 | G3: 9563.1 | H3: =IF(AND(OR('Панель BI'!$C$6="Все","сентябрь 2025"='Панель BI'!$C$6),OR('Панель BI'!$F$6="Все",$B3='Панель BI'!$F$6),OR('Панель BI'!$I$6="Все",$C3='Панель BI'!$I$6)),1,0) | I3: =IF(AND(OR('Панель BI'!$F$6="Все",$B3='Панель BI'!$F$6),OR('Панель BI'!$I$6="Все",$C3='Панель BI'!$I$6)),1,0)
A4: 2025-09 | B4: Бэлць | C4: DIESEL | D4: 238184 | E4: 49 | F4: 816 | G4: 19094.4 | H4: =IF(AND(OR('Панель BI'!$C$6="Все","сентябрь 2025"='Панель BI'!$C$6),OR('Панель BI'!$F$6="Все",$B4='Панель BI'!$F$6),OR('Панель BI'!$I$6="Все",$C4='Панель BI'!$I$6)),1,0) | I4: =IF(AND(OR('Панель BI'!$F$6="Все",$B4='Панель BI'!$F$6),OR('Панель BI'!$I$6="Все",$C4='Панель BI'!$I$6)),1,0)
A5: 2025-09 | B5: Кагул | C5: A92 | D5: 178446 | E5: 37 | F5: 554 | G5: 13406.8 | H5: =IF(AND(OR('Панель BI'!$C$6="Все","сентябрь 2025"='Панель BI'!$C$6),OR('Панель BI'!$F$6="Все",$B5='Панель BI'!$F$6),OR('Панель BI'!$I$6="Все",$C5='Панель BI'!$I$6)),1,0) | I5: =IF(AND(OR('Панель BI'!$F$6="Все",$B5='Панель BI'!$F$6),OR('Панель BI'!$I$6="Все",$C5='Панель BI'!$I$6)),1,0)
A6: 2025-09 | B6: Кагул | C6: A95 | D6: 182115 | E6: 36 | F6: 885 | G6: 22213.5 | H6: =IF(AND(OR('Панель BI'!$C$6="Все","сентябрь 2025"='Панель BI'!$C$6),OR('Панель BI'!$F$6="Все",$B6='Панель BI'!$F$6),OR('Панель BI'!$I$6="Все",$C6='Панель BI'!$I$6)),1,0) | I6: =IF(AND(OR('Панель BI'!$F$6="Все",$B6='Панель BI'!$F$6),OR('Панель BI'!$I$6="Все",$C6='Панель BI'!$I$6)),1,0)
A7: 2025-09 | B7: Кагул | C7: DIESEL | D7: 162555 | E7: 34 | F7: 445 | G7: 10413 | H7: =IF(AND(OR('Панель BI'!$C$6="Все","сентябрь 2025"='Панель BI'!$C$6),OR('Панель BI'!$F$6="Все",$B7='Панель BI'!$F$6),OR('Панель BI'!$I$6="Все",$C7='Панель BI'!$I$6)),1,0) | I7: =IF(AND(OR('Панель BI'!$F$6="Все",$B7='Панель BI'!$F$6),OR('Панель BI'!$I$6="Все",$C7='Панель BI'!$I$6)),1,0)
A8: 2025-09 | B8: Кишинёв | C8: A92 | D8: 193456 | E8: 39 | F8: 544 | G8: 13164.8 | H8: =IF(AND(OR('Панель BI'!$C$6="Все","сентябрь 2025"='Панель BI'!$C$6),OR('Панель BI'!$F$6="Все",$B8='Панель BI'!$F$6),OR('Панель BI'!$I$6="Все",$C8='Панель BI'!$I$6)),1,0) | I8: =IF(AND(OR('Панель BI'!$F$6="Все",$B8='Панель BI'!$F$6),OR('Панель BI'!$I$6="Все",$C8='Панель BI'!$I$6)),1,0)
A9: 2025-09 | B9: Кишинёв | C9: A95 | D9: 198923 | E9: 41 | F9: 1077 | G9: 27032.7 | H9: =IF(AND(OR('Панель BI'!$C$6="Все","сентябрь 2025"='Панель BI'!$C$6),OR('Панель BI'!$F$6="Все",$B9='Панель BI'!$F$6),OR('Панель BI'!$I$6="Все",$C9='Панель BI'!$I$6)),1,0) | I9: =IF(AND(OR('Панель BI'!$F$6="Все",$B9='Панель BI'!$F$6),OR('Панель BI'!$I$6="Все",$C9='Панель BI'!$I$6)),1,0)
A10: 2025-09 | B10: Кишинёв | C10: DIESEL | D10: 172471 | E10: 34 | F10: 529 | G10: 12378.6 | H10: =IF(AND(OR('Панель BI'!$C$6="Все","сентябрь 2025"='Панель BI'!$C$6),OR('Панель BI'!$F$6="Все",$B10='Панель BI'!$F$6),OR('Панель BI'!$I$6="Все",$C10='Панель BI'!$I$6)),1,0) | I10: =IF(AND(OR('Панель BI'!$F$6="Все",$B10='Панель BI'!$F$6),OR('Панель BI'!$I$6="Все",$C10='Панель BI'!$I$6)),1,0)
A11: 2025-09 | B11: Кишинёв | C11: GPL | D11: 35891 | E11: 8 | F11: 109 | G11: 1504.2 | H11: =IF(AND(OR('Панель BI'!$C$6="Все","сентябрь 2025"='Панель BI'!$C$6),OR('Панель BI'!$F$6="Все",$B11='Панель BI'!$F$6),OR('Панель BI'!$I$6="Все",$C11='Панель BI'!$I$6)),1,0) | I11: =IF(AND(OR('Панель BI'!$F$6="Все",$B11='Панель BI'!$F$6),OR('Панель BI'!$I$6="Все",$C11='Панель BI'!$I$6)),1,0)
A12: 2025-09 | B12: Комрат | C12: A92 | D12: 272061 | E12: 54 | F12: 1110 | G12: 26862 | H12: =IF(AND(OR('Панель BI'!$C$6="Все","сентябрь 2025"='Панель BI'!$C$6),OR('Панель BI'!$F$6="Все",$B12='Панель BI'!$F$6),OR('Панель BI'!$I$6="Все",$C12='Панель BI'!$I$6)),1,0) | I12: =IF(AND(OR('Панель BI'!$F$6="Все",$B12='Панель BI'!$F$6),OR('Панель BI'!$I$6="Все",$C12='Панель BI'!$I$6)),1,0)
A13: 2025-09 | B13: Комрат | C13: A95 | D13: 211426 | E13: 43 | F13: 574 | G13: 14407.4 | H13: =IF(AND(OR('Панель BI'!$C$6="Все","сентябрь 2025"='Панель BI'!$C$6),OR('Панель BI'!$F$6="Все",$B13='Панель BI'!$F$6),OR('Панель BI'!$I$6="Все",$C13='Панель BI'!$I$6)),1,0) | I13: =IF(AND(OR('Панель BI'!$F$6="Все",$B13='Панель BI'!$F$6),OR('Панель BI'!$I$6="Все",$C13='Панель BI'!$I$6)),1,0)
... A22: 2025-09 | B22: Унгень | C22: GPL | D22: 29926 | E22: 6 | F22: 74 | G22: 1021.2 | H22: =IF(AND(OR('Панель BI'!$C$6="Все","сентябрь 2025"='Панель BI'!$C$6),OR('Панель BI'!$F$6="Все",$B22='Панель BI'!$F$6),OR('Панель BI'!$I$6="Все",$C22='Панель BI'!$I$6)),1,0) | I22: =IF(AND(OR('Панель BI'!$F$6="Все",$B22='Панель BI'!$F$6),OR('Панель BI'!$I$6="Все",$C22='Панель BI'!$I$6)),1,0)
A23: 2025-10 | B23: Бэлць | C23: A92 | D23: 170476 | E23: 35 | F23: 524 | G23: 12680.8 | H23: =IF(AND(OR('Панель BI'!$C$6="Все","октябрь 2025"='Панель BI'!$C$6),OR('Панель BI'!$F$6="Все",$B23='Панель BI'!$F$6),OR('Панель BI'!$I$6="Все",$C23='Панель BI'!$I$6)),1,0) | I23: =IF(AND(OR('Панель BI'!$F$6="Все",$B23='Панель BI'!$F$6),OR('Панель BI'!$I$6="Все",$C23='Панель BI'!$I$6)),1,0)
A24: 2025-10 | B24: Бэлць | C24: A95 | D24: 198416 | E24: 39 | F24: 584 | G24: 14658.4 | H24: =IF(AND(OR('Панель BI'!$C$6="Все","октябрь 2025"='Панель BI'!$C$6),OR('Панель BI'!$F$6="Все",$B24='Панель BI'!$F$6),OR('Панель BI'!$I$6="Все",$C24='Панель BI'!$I$6)),1,0) | I24: =IF(AND(OR('Панель BI'!$F$6="Все",$B24='Панель BI'!$F$6),OR('Панель BI'!$I$6="Все",$C24='Панель BI'!$I$6)),1,0)
A25: 2025-10 | B25: Бэлць | C25: DIESEL | D25: 255393 | E25: 51 | F25: 607 | G25: 14203.8 | H25: =IF(AND(OR('Панель BI'!$C$6="Все","октябрь 2025"='Панель BI'!$C$6),OR('Панель BI'!$F$6="Все",$B25='Панель BI'!$F$6),OR('Панель BI'!$I$6="Все",$C25='Панель BI'!$I$6)),1,0) | I25: =IF(AND(OR('Панель BI'!$F$6="Все",$B25='Панель BI'!$F$6),OR('Панель BI'!$I$6="Все",$C25='Панель BI'!$I$6)),1,0)
A26: 2025-10 | B26: Кагул | C26: A92 | D26: 193427 | E26: 39 | F26: 573 | G26: 13866.6 | H26: =IF(AND(OR('Панель BI'!$C$6="Все","октябрь 2025"='Панель BI'!$C$6),OR('Панель BI'!$F$6="Все",$B26='Панель BI'!$F$6),OR('Панель BI'!$I$6="Все",$C26='Панель BI'!$I$6)),1,0) | I26: =IF(AND(OR('Панель BI'!$F$6="Все",$B26='Панель BI'!$F$6),OR('Панель BI'!$I$6="Все",$C26='Панель BI'!$I$6)),1,0)
A27: 2025-10 | B27: Кагул | C27: A95 | D27: 198065 | E27: 41 | F27: 935 | G27: 23468.5 | H27: =IF(AND(OR('Панель BI'!$C$6="Все","октябрь 2025"='Панель BI'!$C$6),OR('Панель BI'!$F$6="Все",$B27='Панель BI'!$F$6),OR('Панель BI'!$I$6="Все",$C27='Панель BI'!$I$6)),1,0) | I27: =IF(AND(OR('Панель BI'!$F$6="Все",$B27='Панель BI'!$F$6),OR('Панель BI'!$I$6="Все",$C27='Панель BI'!$I$6)),1,0)
A28: 2025-10 | B28: Кагул | C28: DIESEL | D28: 205575 | E28: 44 | F28: 1425 | G28: 33345 | H28: =IF(AND(OR('Панель BI'!$C$6="Все","октябрь 2025"='Панель BI'!$C$6),OR('Панель BI'!$F$6="Все",$B28='Панель BI'!$F$6),OR('Панель BI'!$I$6="Все",$C28='Панель BI'!$I$6)),1,0) | I28: =IF(AND(OR('Панель BI'!$F$6="Все",$B28='Панель BI'!$F$6),OR('Панель BI'!$I$6="Все",$C28='Панель BI'!$I$6)),1,0)
A29: 2025-10 | B29: Кишинёв | C29: A92 | D29: 210397 | E29: 42 | F29: 603 | G29: 14592.6 | H29: =IF(AND(OR('Панель BI'!$C$6="Все","октябрь 2025"='Панель BI'!$C$6),OR('Панель BI'!$F$6="Все",$B29='Панель BI'!$F$6),OR('Панель BI'!$I$6="Все",$C29='Панель BI'!$I$6)),1,0) | I29: =IF(AND(OR('Панель BI'!$F$6="Все",$B29='Панель BI'!$F$6),OR('Панель BI'!$I$6="Все",$C29='Панель BI'!$I$6)),1,0)
A30: 2025-10 | B30: Кишинёв | C30: A95 | D30: 202395 | E30: 39 | F30: 605 | G30: 15185.5 | H30: =IF(AND(OR('Панель BI'!$C$6="Все","октябрь 2025"='Панель BI'!$C$6),OR('Панель BI'!$F$6="Все",$B30='Панель BI'!$F$6),OR('Панель BI'!$I$6="Все",$C30='Панель BI'!$I$6)),1,0) | I30: =IF(AND(OR('Панель BI'!$F$6="Все",$B30='Панель BI'!$F$6),OR('Панель BI'!$I$6="Все",$C30='Панель BI'!$I$6)),1,0)
A31: 2025-10 | B31: Кишинёв | C31: DIESEL | D31: 201471 | E31: 40 | F31: 529 | G31: 12378.6 | H31: =IF(AND(OR('Панель BI'!$C$6="Все","октябрь 2025"='Панель BI'!$C$6),OR('Панель BI'!$F$6="Все",$B31='Панель BI'!$F$6),OR('Панель BI'!$I$6="Все",$C31='Панель BI'!$I$6)),1,0) | I31: =IF(AND(OR('Панель BI'!$F$6="Все",$B31='Панель BI'!$F$6),OR('Панель BI'!$I$6="Все",$C31='Панель BI'!$I$6)),1,0)
A32: 2025-10 | B32: Кишинёв | C32: GPL | D32: 41866 | E32: 8 | F32: 134 | G32: 1849.2 | H32: =IF(AND(OR('Панель BI'!$C$6="Все","октябрь 2025"='Панель BI'!$C$6),OR('Панель BI'!$F$6="Все",$B32='Панель BI'!$F$6),OR('Панель BI'!$I$6="Все",$C32='Панель BI'!$I$6)),1,0) | I32: =IF(AND(OR('Панель BI'!$F$6="Все",$B32='Панель BI'!$F$6),OR('Панель BI'!$I$6="Все",$C32='Панель BI'!$I$6)),1,0)
A33: 2025-10 | B33: Комрат | C33: A92 | D33: 184470 | E33: 37 | F33: 530 | G33: 12826 | H33: =IF(AND(OR('Панель BI'!$C$6="Все","октябрь 2025"='Панель BI'!$C$6),OR('Панель BI'!$F$6="Все",$B33='Панель BI'!$F$6),OR('Панель BI'!$I$6="Все",$C33='Панель BI'!$I$6)),1,0) | I33: =IF(AND(OR('Панель BI'!$F$6="Все",$B33='Панель BI'!$F$6),OR('Панель BI'!$I$6="Все",$C33='Панель BI'!$I$6)),1,0)
A34: 2025-10 | B34: Комрат | C34: A95 | D34: 237070 | E34: 49 | F34: 930 | G34: 23343 | H34: =IF(AND(OR('Панель BI'!$C$6="Все","октябрь 2025"='Панель BI'!$C$6),OR('Панель BI'!$F$6="Все",$B34='Панель BI'!$F$6),OR('Панель BI'!$I$6="Все",$C34='Панель BI'!$I$6)),1,0) | I34: =IF(AND(OR('Панель BI'!$F$6="Все",$B34='Панель BI'!$F$6),OR('Панель BI'!$I$6="Все",$C34='Панель BI'!$I$6)),1,0)
... A43: 2025-10 | B43: Унгень | C43: GPL | D43: 38910 | E43: 8 | F43: 90 | G43: 1242 | H43: =IF(AND(OR('Панель BI'!$C$6="Все","октябрь 2025"='Панель BI'!$C$6),OR('Панель BI'!$F$6="Все",$B43='Панель BI'!$F$6),OR('Панель BI'!$I$6="Все",$C43='Панель BI'!$I$6)),1,0) | I43: =IF(AND(OR('Панель BI'!$F$6="Все",$B43='Панель BI'!$F$6),OR('Панель BI'!$I$6="Все",$C43='Панель BI'!$I$6)),1,0)
A44: 2025-11 | B44: Бэлць | C44: A92 | D44: 226216 | E44: 46 | F44: 784 | G44: 18972.8 | H44: =IF(AND(OR('Панель BI'!$C$6="Все","ноябрь 2025"='Панель BI'!$C$6),OR('Панель BI'!$F$6="Все",$B44='Панель BI'!$F$6),OR('Панель BI'!$I$6="Все",$C44='Панель BI'!$I$6)),1,0) | I44: =IF(AND(OR('Панель BI'!$F$6="Все",$B44='Панель BI'!$F$6),OR('Панель BI'!$I$6="Все",$C44='Панель BI'!$I$6)),1,0)
A45: 2025-11 | B45: Бэлць | C45: A95 | D45: 232276 | E45: 48 | F45: 724 | G45: 18172.4 | H45: =IF(AND(OR('Панель BI'!$C$6="Все","ноябрь 2025"='Панель BI'!$C$6),OR('Панель BI'!$F$6="Все",$B45='Панель BI'!$F$6),OR('Панель BI'!$I$6="Все",$C45='Панель BI'!$I$6)),1,0) | I45: =IF(AND(OR('Панель BI'!$F$6="Все",$B45='Панель BI'!$F$6),OR('Панель BI'!$I$6="Все",$C45='Панель BI'!$I$6)),1,0)
A46: 2025-11 | B46: Бэлць | C46: DIESEL | D46: 240191 | E46: 48 | F46: 809 | G46: 18930.6 | H46: =IF(AND(OR('Панель BI'!$C$6="Все","ноябрь 2025"='Панель BI'!$C$6),OR('Панель BI'!$F$6="Все",$B46='Панель BI'!$F$6),OR('Панель BI'!$I$6="Все",$C46='Панель BI'!$I$6)),1,0) | I46: =IF(AND(OR('Панель BI'!$F$6="Все",$B46='Панель BI'!$F$6),OR('Панель BI'!$I$6="Все",$C46='Панель BI'!$I$6)),1,0)
A47: 2025-11 | B47: Кагул | C47: A92 | D47: 176549 | E47: 36 | F47: 451 | G47: 10914.2 | H47: =IF(AND(OR('Панель BI'!$C$6="Все","ноябрь 2025"='Панель BI'!$C$6),OR('Панель BI'!$F$6="Все",$B47='Панель BI'!$F$6),OR('Панель BI'!$I$6="Все",$C47='Панель BI'!$I$6)),1,0) | I47: =IF(AND(OR('Панель BI'!$F$6="Все",$B47='Панель BI'!$F$6),OR('Панель BI'!$I$6="Все",$C47='Панель BI'!$I$6)),1,0)
A48: 2025-11 | B48: Кагул | C48: A95 | D48: 169561 | E48: 33 | F48: 439 | G48: 11018.9 | H48: =IF(AND(OR('Панель BI'!$C$6="Все","ноябрь 2025"='Панель BI'!$C$6),OR('Панель BI'!$F$6="Все",$B48='Панель BI'!$F$6),OR('Панель BI'!$I$6="Все",$C48='Панель BI'!$I$6)),1,0) | I48: =IF(AND(OR('Панель BI'!$F$6="Все",$B48='Панель BI'!$F$6),OR('Панель BI'!$I$6="Все",$C48='Панель BI'!$I$6)),1,0)
A49: 2025-11 | B49: Кагул | C49: DIESEL | D49: 225079 | E49: 44 | F49: 921 | G49: 21551.4 | H49: =IF(AND(OR('Панель BI'!$C$6="Все","ноябрь 2025"='Панель BI'!$C$6),OR('Панель BI'!$F$6="Все",$B49='Панель BI'!$F$6),OR('Панель BI'!$I$6="Все",$C49='Панель BI'!$I$6)),1,0) | I49: =IF(AND(OR('Панель BI'!$F$6="Все",$B49='Панель BI'!$F$6),OR('Панель BI'!$I$6="Все",$C49='Панель BI'!$I$6)),1,0)
A50: 2025-11 | B50: Кишинёв | C50: A92 | D50: 146590 | E50: 30 | F50: 410 | G50: 9922 | H50: =IF(AND(OR('Панель BI'!$C$6="Все","ноябрь 2025"='Панель BI'!$C$6),OR('Панель BI'!$F$6="Все",$B50='Панель BI'!$F$6),OR('Панель BI'!$I$6="Все",$C50='Панель BI'!$I$6)),1,0) | I50: =IF(AND(OR('Панель BI'!$F$6="Все",$B50='Панель BI'!$F$6),OR('Панель BI'!$I$6="Все",$C50='Панель BI'!$I$6)),1,0)
A51: 2025-11 | B51: Кишинёв | C51: A95 | D51: 192351 | E51: 38 | F51: 649 | G51: 16289.9 | H51: =IF(AND(OR('Панель BI'!$C$6="Все","ноябрь 2025"='Панель BI'!$C$6),OR('Панель BI'!$F$6="Все",$B51='Панель BI'!$F$6),OR('Панель BI'!$I$6="Все",$C51='Панель BI'!$I$6)),1,0) | I51: =IF(AND(OR('Панель BI'!$F$6="Все",$B51='Панель BI'!$F$6),OR('Панель BI'!$I$6="Все",$C51='Панель BI'!$I$6)),1,0)
A52: 2025-11 | B52: Кишинёв | C52: DIESEL | D52: 240336 | E52: 47 | F52: 664 | G52: 15537.6 | H52: =IF(AND(OR('Панель BI'!$C$6="Все","ноябрь 2025"='Панель BI'!$C$6),OR('Панель BI'!$F$6="Все",$B52='Панель BI'!$F$6),OR('Панель BI'!$I$6="Все",$C52='Панель BI'!$I$6)),1,0) | I52: =IF(AND(OR('Панель BI'!$F$6="Все",$B52='Панель BI'!$F$6),OR('Панель BI'!$I$6="Все",$C52='Панель BI'!$I$6)),1,0)
A53: 2025-11 | B53: Кишинёв | C53: GPL | D53: 66774 | E53: 14 | F53: 226 | G53: 3118.8 | H53: =IF(AND(OR('Панель BI'!$C$6="Все","ноябрь 2025"='Панель BI'!$C$6),OR('Панель BI'!$F$6="Все",$B53='Панель BI'!$F$6),OR('Панель BI'!$I$6="Все",$C53='Панель BI'!$I$6)),1,0) | I53: =IF(AND(OR('Панель BI'!$F$6="Все",$B53='Панель BI'!$F$6),OR('Панель BI'!$I$6="Все",$C53='Панель BI'!$I$6)),1,0)
A54: 2025-11 | B54: Комрат | C54: A92 | D54: 157529 | E54: 32 | F54: 471 | G54: 11398.2 | H54: =IF(AND(OR('Панель BI'!$C$6="Все","ноябрь 2025"='Панель BI'!$C$6),OR('Панель BI'!$F$6="Все",$B54='Панель BI'!$F$6),OR('Панель BI'!$I$6="Все",$C54='Панель BI'!$I$6)),1,0) | I54: =IF(AND(OR('Панель BI'!$F$6="Все",$B54='Панель BI'!$F$6),OR('Панель BI'!$I$6="Все",$C54='Панель BI'!$I$6)),1,0)
A55: 2025-11 | B55: Комрат | C55: A95 | D55: 162429 | E55: 33 | F55: 571 | G55: 14332.1 | H55: =IF(AND(OR('Панель BI'!$C$6="Все","ноябрь 2025"='Панель BI'!$C$6),OR('Панель BI'!$F$6="Все",$B55='Панель BI'!$F$6),OR('Панель BI'!$I$6="Все",$C55='Панель BI'!$I$6)),1,0) | I55: =IF(AND(OR('Панель BI'!$F$6="Все",$B55='Панель BI'!$F$6),OR('Панель BI'!$I$6="Все",$C55='Панель BI'!$I$6)),1,0)
... A64: 2025-11 | B64: Унгень | C64: GPL | D64: 56827 | E64: 11 | F64: 173 | G64: 2387.4 | H64: =IF(AND(OR('Панель BI'!$C$6="Все","ноябрь 2025"='Панель BI'!$C$6),OR('Панель BI'!$F$6="Все",$B64='Панель BI'!$F$6),OR('Панель BI'!$I$6="Все",$C64='Панель BI'!$I$6)),1,0) | I64: =IF(AND(OR('Панель BI'!$F$6="Все",$B64='Панель BI'!$F$6),OR('Панель BI'!$I$6="Все",$C64='Панель BI'!$I$6)),1,0)
...

Sheet КубРейсы
A1: Месяц | B1: Тип рейса | C1: Рейсов | D1: Норматив, км | E1: Факт, км | F1: Лишний пробег, км | G1: Начислено, лей | H1: Норма ДТ, л | I1: Факт ДТ, л | J1: В срезе | K1: В срезе без месяца
A2: 2025-09 | B2: DOMESTIC | C2: 228 | D2: 70839 | E2: 72336 | F2: 1621 | G2: 329754.01 | H2: 23465 | I2: 23540 | J2: =IF(AND(OR('Панель BI'!$C$6="Все","сентябрь 2025"='Панель BI'!$C$6),OR('Панель BI'!$L$6="Все",$B2='Панель BI'!$L$6)),1,0) | K2: =IF(OR('Панель BI'!$L$6="Все",$B2='Панель BI'!$L$6),1,0)
A3: 2025-09 | B3: IMPORT | C3: 38 | D3: 32960 | E3: 33711 | F3: 811 | G3: 90639.99 | H3: 10836 | I3: 10949 | J3: =IF(AND(OR('Панель BI'!$C$6="Все","сентябрь 2025"='Панель BI'!$C$6),OR('Панель BI'!$L$6="Все",$B3='Панель BI'!$L$6)),1,0) | K3: =IF(OR('Панель BI'!$L$6="Все",$B3='Панель BI'!$L$6),1,0)
A4: 2025-10 | B4: DOMESTIC | C4: 212 | D4: 63274 | E4: 64319 | F4: 1181 | G4: 300392.69 | H4: 20893 | I4: 21032 | J4: =IF(AND(OR('Панель BI'!$C$6="Все","октябрь 2025"='Панель BI'!$C$6),OR('Панель BI'!$L$6="Все",$B4='Панель BI'!$L$6)),1,0) | K4: =IF(OR('Панель BI'!$L$6="Все",$B4='Панель BI'!$L$6),1,0)
A5: 2025-10 | B5: IMPORT | C5: 54 | D5: 49866 | E5: 51344 | F5: 1531 | G5: 134005.06 | H5: 16431 | I5: 16515 | J5: =IF(AND(OR('Панель BI'!$C$6="Все","октябрь 2025"='Панель BI'!$C$6),OR('Панель BI'!$L$6="Все",$B5='Панель BI'!$L$6)),1,0) | K5: =IF(OR('Панель BI'!$L$6="Все",$B5='Панель BI'!$L$6),1,0)
A6: 2025-11 | B6: DOMESTIC | C6: 204 | D6: 62403 | E6: 63523 | F6: 1210 | G6: 294096.78 | H6: 20663 | I6: 20788 | J6: =IF(AND(OR('Панель BI'!$C$6="Все","ноябрь 2025"='Панель BI'!$C$6),OR('Панель BI'!$L$6="Все",$B6='Панель BI'!$L$6)),1,0) | K6: =IF(OR('Панель BI'!$L$6="Все",$B6='Панель BI'!$L$6),1,0)
A7: 2025-11 | B7: IMPORT | C7: 52 | D7: 44933 | E7: 45719 | F7: 873 | G7: 121101.2 | H7: 14823 | I7: 14872 | J7: =IF(AND(OR('Панель BI'!$C$6="Все","ноябрь 2025"='Панель BI'!$C$6),OR('Панель BI'!$L$6="Все",$B7='Панель BI'!$L$6)),1,0) | K7: =IF(OR('Панель BI'!$L$6="Все",$B7='Панель BI'!$L$6),1,0)
A8: 2025-12 | B8: DOMESTIC | C8: 237 | D8: 70460 | E8: 71694 | F8: 1382 | G8: 334621.18 | H8: 23273 | I8: 23499 | J8: =IF(AND(OR('Панель BI'!$C$6="Все","декабрь 2025"='Панель BI'!$C$6),OR('Панель BI'!$L$6="Все",$B8='Панель BI'!$L$6)),1,0) | K8: =IF(OR('Панель BI'!$L$6="Все",$B8='Панель BI'!$L$6),1,0)
A9: 2025-12 | B9: IMPORT | C9: 59 | D9: 50577 | E9: 51615 | F9: 1146 | G9: 139333.04 | H9: 16819 | I9: 16887 | J9: =IF(AND(OR('Панель BI'!$C$6="Все","декабрь 2025"='Панель BI'!$C$6),OR('Панель BI'!$L$6="Все",$B9='Панель BI'!$L$6)),1,0) | K9: =IF(OR('Панель BI'!$L$6="Все",$B9='Панель BI'!$L$6),1,0)
A10: 2026-01 | B10: DOMESTIC | C10: 226 | D10: 67736 | E10: 69099 | F10: 1465 | G10: 320536.16 | H10: 22300 | I10: 22387 | J10: =IF(AND(OR('Панель BI'!$C$6="Все","январь 2026"='Панель BI'!$C$6),OR('Панель BI'!$L$6="Все",$B10='Панель BI'!$L$6)),1,0) | K10: =IF(OR('Панель BI'!$L$6="Все",$B10='Панель BI'!$L$6),1,0)
A11: 2026-01 | B11: IMPORT | C11: 57 | D11: 49074 | E11: 49823 | F11: 818 | G11: 134954.89 | H11: 16397 | I11: 16468 | J11: =IF(AND(OR('Панель BI'!$C$6="Все","январь 2026"='Панель BI'!$C$6),OR('Панель BI'!$L$6="Все",$B11='Панель BI'!$L$6)),1,0) | K11: =IF(OR('Панель BI'!$L$6="Все",$B11='Панель BI'!$L$6),1,0)
A12: 2026-02 | B12: DOMESTIC | C12: 198 | D12: 58947 | E12: 60316 | F12: 1446 | G12: 279285.08 | H12: 19433 | I12: 19448 | J12: =IF(AND(OR('Панель BI'!$C$6="Все","февраль 2026"='Панель BI'!$C$6),OR('Панель BI'!$L$6="Все",$B12='Панель BI'!$L$6)),1,0) | K12: =IF(OR('Панель BI'!$L$6="Все",$B12='Панель BI'!$L$6),1,0)
A13: 2026-02 | B13: IMPORT | C13: 51 | D13: 44302 | E13: 45258 | F13: 1034 | G13: 121829.7 | H13: 14742 | I13: 14848 | J13: =IF(AND(OR('Панель BI'!$C$6="Все","февраль 2026"='Панель BI'!$C$6),OR('Панель BI'!$L$6="Все",$B13='Панель BI'!$L$6)),1,0) | K13: =IF(OR('Панель BI'!$L$6="Все",$B13='Панель BI'!$L$6),1,0)
A14: 2026-03 | B14: DOMESTIC | C14: 233 | D14: 72373 | E14: 73854 | F14: 1633 | G14: 337511.27 | H14: 23942 | I14: 24042 | J14: =IF(AND(OR('Панель BI'!$C$6="Все","март 2026"='Панель BI'!$C$6),OR('Панель BI'!$L$6="Все",$B14='Панель BI'!$L$6)),1,0) | K14: =IF(OR('Панель BI'!$L$6="Все",$B14='Панель BI'!$L$6),1,0)
A15: 2026-03 | B15: IMPORT | C15: 49 | D15: 44574 | E15: 45470 | F15: 978 | G15: 122578.54 | H15: 14722 | I15: 14777 | J15: =IF(AND(OR('Панель BI'!$C$6="Все","март 2026"='Панель BI'!$C$6),OR('Панель BI'!$L$6="Все",$B15='Панель BI'!$L$6)),1,0) | K15: =IF(OR('Панель BI'!$L$6="Все",$B15='Панель BI'!$L$6),1,0)
A16: 2026-04 | B16: DOMESTIC | C16: 236 | D16: 70982 | E16: 72580 | F16: 1731 | G16: 334270.54 | H16: 23499 | I16: 23610 | J16: =IF(AND(OR('Панель BI'!$C$6="Все","апрель 2026"='Панель BI'!$C$6),OR('Панель BI'!$L$6="Все",$B16='Панель BI'!$L$6)),1,0) | K16: =IF(OR('Панель BI'!$L$6="Все",$B16='Панель BI'!$L$6),1,0)
A17: 2026-04 | B17: IMPORT | C17: 41 | D17: 36660 | E17: 37444 | F17: 816 | G17: 95475.35 | H17: 12172 | I17: 12307 | J17: =IF(AND(OR('Панель BI'!$C$6="Все","апрель 2026"='Панель BI'!$C$6),OR('Панель BI'!$L$6="Все",$B17='Панель BI'!$L$6)),1,0) | K17: =IF(OR('Панель BI'!$L$6="Все",$B17='Панель BI'!$L$6),1,0)
A18: 2026-05 | B18: DOMESTIC | C18: 209 | D18: 62272 | E18: 63377 | F18: 1208 | G18: 291568.73 | H18: 20530 | I18: 20668 | J18: =IF(AND(OR('Панель BI'!$C$6="Все","май 2026"='Панель BI'!$C$6),OR('Панель BI'!$L$6="Все",$B18='Панель BI'!$L$6)),1,0) | K18: =IF(OR('Панель BI'!$L$6="Все",$B18='Панель BI'!$L$6),1,0)
A19: 2026-05 | B19: IMPORT | C19: 57 | D19: 50133 | E19: 51350 | F19: 1273 | G19: 137866.31 | H19: 16541 | I19: 16538 | J19: =IF(AND(OR('Панель BI'!$C$6="Все","май 2026"='Панель BI'!$C$6),OR('Панель BI'!$L$6="Все",$B19='Панель BI'!$L$6)),1,0) | K19: =IF(OR('Панель BI'!$L$6="Все",$B19='Панель BI'!$L$6),1,0)
A20: 2026-06 | B20: DOMESTIC | C20: 227 | D20: 68082 | E20: 69566 | F20: 1577 | G20: 322970.91 | H20: 22570 | I20: 22715 | J20: =IF(AND(OR('Панель BI'!$C$6="Все","июнь 2026"='Панель BI'!$C$6),OR('Панель BI'!$L$6="Все",$B20='Панель BI'!$L$6)),1,0) | K20: =IF(OR('Панель BI'!$L$6="Все",$B20='Панель BI'!$L$6),1,0)
A21: 2026-06 | B21: IMPORT | C21: 39 | D21: 35958 | E21: 36619 | F21: 737 | G21: 98884.51 | H21: 11748 | I21: 11927 | J21: =IF(AND(OR('Панель BI'!$C$6="Все","июнь 2026"='Панель BI'!$C$6),OR('Панель BI'!$L$6="Все",$B21='Панель BI'!$L$6)),1,0) | K21: =IF(OR('Панель BI'!$L$6="Все",$B21='Панель BI'!$L$6),1,0)
A22: 2026-07 | B22: DOMESTIC | C22: 239 | D22: 71628 | E22: 73130 | F22: 1634 | G22: 340377.47 | H22: 23663 | I22: 23729 | J22: =IF(AND(OR('Панель BI'!$C$6="Все","июль 2026"='Панель BI'!$C$6),OR('Панель BI'!$L$6="Все",$B22='Панель BI'!$L$6)),1,0) | K22: =IF(OR('Панель BI'!$L$6="Все",$B22='Панель BI'!$L$6),1,0)
A23: 2026-07 | B23: IMPORT | C23: 48 | D23: 41721 | E23: 42647 | F23: 1029 | G23: 114732.75 | H23: 13820 | I23: 13865 | J23: =IF(AND(OR('Панель BI'!$C$6="Все","июль 2026"='Панель BI'!$C$6),OR('Панель BI'!$L$6="Все",$B23='Панель BI'!$L$6)),1,0) | K23: =IF(OR('Панель BI'!$L$6="Все",$B23='Панель BI'!$L$6),1,0)
A24: 2026-08 | B24: DOMESTIC | C24: 232 | D24: 69275 | E24: 70446 | F24: 1310 | G24: 329957.05 | H24: 22919 | I24: 23082 | J24: =IF(AND(OR('Панель BI'!$C$6="Все","август 2026"='Панель BI'!$C$6),OR('Панель BI'!$L$6="Все",$B24='Панель BI'!$L$6)),1,0) | K24: =IF(OR('Панель BI'!$L$6="Все",$B24='Панель BI'!$L$6),1,0)
A25: 2026-08 | B25: IMPORT | C25: 42 | D25: 35666 | E25: 36542 | F25: 907 | G25: 98081.2 | H25: 11883 | I25: 12094 | J25: =IF(AND(OR('Панель BI'!$C$6="Все","август 2026"='Панель BI'!$C$6),OR('Панель BI'!$L$6="Все",$B25='Панель BI'!$L$6)),1,0) | K25: =IF(OR('Панель BI'!$L$6="Все",$B25='Панель BI'!$L$6),1,0)
A26: 2026-09 | B26: DOMESTIC | C26: 223 | D26: 69304 | E26: 71028 | F26: 1845 | G26: 242747.63 | H26: 22842 | I26: 22968 | J26: =IF(AND(OR('Панель BI'!$C$6="Все","сентябрь 2026"='Панель BI'!$C$6),OR('Панель BI'!$L$6="Все",$B26='Панель BI'!$L$6)),1,0) | K26: =IF(OR('Панель BI'!$L$6="Все",$B26='Панель BI'!$L$6),1,0)
A27: 2026-09 | B27: IMPORT | C27: 43 | D27: 38057 | E27: 38720 | F27: 713 | G27: 130827.9 | H27: 12659 | I27: 12825 | J27: =IF(AND(OR('Панель BI'!$C$6="Все","сентябрь 2026"='Панель BI'!$C$6),OR('Панель BI'!$L$6="Все",$B27='Панель BI'!$L$6)),1,0) | K27: =IF(OR('Панель BI'!$L$6="Все",$B27='Панель BI'!$L$6),1,0)

Sheet Самопроверка
A2: Самопроверка методики
A3: Лист существует только для сгенерированного набора: в него намеренно заложено известное число дефектов каждого вида.
A5: Зачем это нужно
A6: • Проверка, которой нечего находить, ничего не доказывает: она одинаково молчит и когда всё чисто, и когда сама сломана.
A7: • Поэтому набор данных генерируется с известным числом нарушений каждого вида, а проверка прогоняется вслепую. Совпадение «подложено» и «найдено» по всем процедурам — доказательство, что методика ловит то, что должна, и не выдумывает лишнего.
